Workbook
Name OMA: Tabelle1[#All]
Name OMA: Tabelle1[#All]
Name OMA: Tabelle1[#All]

Sheet cheat sheet
A1: Hallo, Willkommen bei dem Excel-Einstufungs-Test. Lass uns herausfinden, was du kannst und wo du dich noch verbessern kannst.
A3: Navigation zwischen direkt benachbarten Zellen | B3: mit Pfeiltasten
A4: Bildschirmseiten auf- / abwärts | B4: Bild ↑, Bild ↓
A5: An das Ende/den Anfang einer Tabelle springen | B5: Strg + Pfeiltaste
A6: An das Ende eines Tabellenblatts springen | B6: Strg + Ende
A7: An den Anfang eines Tabellenblatts springen | B7: Strg + Pos1
A8: Zusammenhängende Zellen markieren | B8: Umschalt gedrückt halten + Pfeiltasten
A9: Zusammenhängende Bereiche markieren | B9: Strg + Umschalt + Pfeiltasten
A10: Absoluten/Relativen Wert/Zeile/Spalte ändern | B10: F4
A11: Spaltenbreite/Zeilenhöhe automatisch optimieren | B11: Doppelklick zwischen zwei Spalten oder Zeilen
A13: WORK IN PROGRESS

Sheet Aufgabe1
A1: In den Zeilen 11-16 sind ein paar Daten, die von einem Mitarbeiter schlecht formatiert wurden. Passe diese bitte dem folgenden Design an.
A2: Die untere Tabelle soll, die gleichen Rahmen, Füllungen und Zahlen/Textformate wie die obere Tabelle haben.
A3: Die Spaltenüberschriften sind für vier Quartale, die letzte Spalte enthält die Summe aller Quartale.
A5: Spalte1 | B5: Spalte2 | C5: Spalte3 | D5: Spalte4 | E5: Summe
A6: 1 | B6: 2 | C6: 3 | D6: 4 | E6: =SUM(A6:D6) -> 10
A7: 6 | B7: 7 | C7: 8 | D7: 9 | E7: =SUM(A7:D7) -> 30
A9: Zudem soll in der letzten Spalte jeweils das Ergebnis der vier Quartale aufsummiert werden. Benutze dafür eine Funktion von Excel.
A10: Die Zellen sollen als Zahlenformat Währung dargestellt werden.
A12: Quartal1 | B12: Quartal2 | C12: Quartal3 | D12: Quartal4 | E12: Summe
A13: 789 | B13: 84 | C13: 33 | D13: 54
A14: 32 | B14: 473 | C14: 1 | D14: 76
A15: 4123 | B15: 6457 | C15: 3 | D15: 47
A16: 22 | B16: 236 | C16: 57 | D16: 234
A17: 9 | B17: 289 | C17: 662 | D17: 4

Sheet Aufgabe1 Lösung
A1: In den Zeilen 11-16 sind ein paar Daten, die von einem Mitarbeiter schlecht formatiert wurden. Passe diese bitte dem folgenden Format an.
A2: Die untere Tabelle soll, die gleichen Rahmen, Füllungen und Zahlen/Textformate wie die obere Tabelle haben.
A3: Die Spaltenüberschriften sind für vier Quartale, die letzte Spalte enthält die Summe aller Quartale.
A5: Spalte1 | B5: Spalte2 | C5: Spalte3 | D5: Spalte4 | E5: Summe
A6: 1 | B6: 2 | C6: 3 | D6: 4 | E6: =SUM(A6:D6) -> 10
A7: 6 | B7: 7 | C7: 8 | D7: 9 | E7: =SUM(A7:D7) -> 30
A9: Zudem soll in der letzten Spalte jeweils das Ergebnis der vier Quartale aufsummiert werden. Benutze dafür eine Funktion von Excel.
A10: Die Zellen sollen als Zahlenformat Währung dargestellt werden.
A12: Quartal1 | B12: Quartal2 | C12: Quartal3 | D12: Quartal4 | E12: Summe
A13: 789 | B13: 84 | C13: 33 | D13: 54 | E13: =SUM(A13:D13) -> 960
A14: 32 | B14: 473 | C14: 1 | D14: 76 | E14: =SUM(A14:D14) -> 582
A15: 4123 | B15: 6457 | C15: 3 | D15: 47 | E15: =SUM(A15:D15) -> 10630
A16: 22 | B16: 236 | C16: 57 | D16: 234 | E16: =SUM(A16:D16) -> 549
A17: 9 | B17: 289 | C17: 662 | D17: 4 | E17: =SUM(A17:D17) -> 964

Sheet Aufgabe2
A1: Super, du hast die erste Aufgabe geschafft.
A3: In folgendem Feld soll die Umsatzsteuer von 19 % stehen. Trage diese bitte in das rot markierte Feld ein
A5: Du hast die Aufgabe bekommen, die Liste rechts in Excel zu übertragen und mit diesen Daten einige Auswertungen vorzunehmen
A6: Dazu sollst du die vorgefertige Liste verwenden und die Werte einzutragen bzw. berechnen lassen
A7: Datum: Soll einfach übernommen werden. (Auto-Funktion verwenden)
A8: Stück: Soll einfach übernommen werden
A9: Retour: Soll einfach übernommen werden
A10: Tagesumsatz brutto: Soll einfach übernommen werden
A11: Stück ohne Retour: Soll für jeden Tag die tatsächliche Stückzahl (Stück - Retouren) ausgeben
A12: Umsatz/Stück brutto: Soll den Umsatz auf die tatsächliche Stückzahl berechnen (Format: in € mit zwei Nachkommastellen)
A13: Retourenquote: Prozentzahl, die angibt, wie viel der gesamten Stück retourniert wurden
A14: Tagesumsatz netto: Gibt den tatsächlichen Umsatz in Abhängigkeit des Wertes von G3 an (= brutto / (100% + USt))
A17: Datum | B17: Stück | C17: Retour | D17: Tagesumsatz brutto | E17: Stück ohne Retour | F17: Umsatz/Stück brutto | G17: Retourenquote | H17: Tagesumsatz netto
A29: Zudem sollen zwei einfache Diagramme angezeigt werden. Das erste soll ein Liniendiagramm sein, welches den zeitlichen Verlauf des Bruttoumsatzes anzeigt.
A30: Das zweite Diagramm soll ein kombiniertes Säulen und Liniendiagramm sein: Umsatz/Stück als Säulen und Retourenquote als Linie. Dazu sind zwei Y-Achsen zu verwenden

Sheet Aufgabe2 Lösung
A1: Super, du hast die erste Aufgabe geschafft.
A3: In folgendem Feld soll die Umsatzsteuer von 19 % stehen. Trage diese bitte in das rot markierte Feld ein | G3: 0.19
A5: Du hast die Aufgabe bekommen, die Liste rechts in Excel zu übertragen und mit diesen Daten einige Auswertungen vorzunehmen
A6: Dazu sollst du die vorgefertige Liste verwenden und die Werte eintragen bzw. berechnen lassen
A7: Datum: Soll einfach übernommen werden. (Auto-Funktion verwenden)
A8: Stück: Soll einfach übernommen werden
A9: Retour: Soll einfach übernommen werden
A10: Tagesumsatz brutto: Soll einfach übernommen werden
A11: Stück ohne Retour: Soll für jeden Tag die tatsächliche Stückzahl (Stück - Retouren) ausgeben
A12: Umsatz/Stück brutto: Soll den Umsatz pro Einheit für die tatsächliche Stückzahl berechnen (Format: in € mit zwei Nachkommastellen)
A13: Retourenquote: Prozentzahl, die angibt, wie viel der gesamten Stück retourniert wurden
A14: Tagesumsatz netto: Gibt den tatsächlichen Umsatz in Abhängigkeit des Wertes von G3 an (= brutto / (100% + USt))
A17: Datum | B17: Stück | C17: Retour | D17: Tagesumsatz brutto | E17: Stück ohne Retour | F17: Umsatz/Stück brutto | G17: Retourenquote | H17: Tagesumsatz netto
A18: 43556 | B18: 40 | C18: 12 | D18: 90 | E18: =B18-C18 -> 28 | F18: =D18/E18 -> 3.2142857 | G18: =C18/B18 -> 0.3 | H18: =D18/(1+$G$3) -> 75.630252
A19: 43557 | B19: 30 | C19: 8 | D19: 60.56 | E19: =B19-C19 -> 22 | F19: =D19/E19 -> 2.7527273 | G19: =C19/B19 -> 0.26666667 | H19: =D19/(1+$G$3) -> 50.890756
A20: 43558 | B20: 78 | C20: 14 | D20: 23.63 | E20: =B20-C20 -> 64 | F20: =D20/E20 -> 0.36921875 | G20: =C20/B20 -> 0.17948718 | H20: =D20/(1+$G$3) -> 19.857143
A21: 43559 | B21: 28 | C21: 2 | D21: 78.43 | E21: =B21-C21 -> 26 | F21: =D21/E21 -> 3.0165385 | G21: =C21/B21 -> 0.071428571 | H21: =D21/(1+$G$3) -> 65.907563
A22: 43560 | B22: 12 | C22: 5 | D22: 39.59 | E22: =B22-C22 -> 7 | F22: =D22/E22 -> 5.6557143 | G22: =C22/B22 -> 0.41666667 | H22: =D22/(1+$G$3) -> 33.268908
A23: 43561 | B23: 56 | C23: 23 | D23: 29.99 | E23: =B23-C23 -> 33 | F23: =D23/E23 -> 0.90878788 | G23: =C23/B23 -> 0.41071429 | H23: =D23/(1+$G$3) -> 25.201681
A24: 43562 | B24: 34 | C24: 7 | D24: 12.75 | E24: =B24-C24 -> 27 | F24: =D24/E24 -> 0.47222222 | G24: =C24/B24 -> 0.20588235 | H24: =D24/(1+$G$3) -> 10.714286
A25: 43563 | B25: 19 | C25: 1 | D25: 34.86 | E25: =B25-C25 -> 18 | F25: =D25/E25 -> 1.9366667 | G25: =C25/B25 -> 0.052631579 | H25: =D25/(1+$G$3) -> 29.294118
A26: 43564 | B26: 104 | C26: 28 | D26: 21.31 | E26: =B26-C26 -> 76 | F26: =D26/E26 -> 0.28039474 | G26: =C26/B26 -> 0.26923077 | H26: =D26/(1+$G$3) -> 17.907563
A27: 43565 | B27: 45 | C27: 17 | D27: 64.23 | E27: =B27-C27 -> 28 | F27: =D27/E27 -> 2.2939286 | G27: =C27/B27 -> 0.37777778 | H27: =D27/(1+$G$3) -> 53.97479
A29: Zudem sollen zwei einfache Diagramme angezeigt werden. Das erste soll ein Liniendiagramm sein, welches den zeitlichen Verlauf des Bruttoumsatzes anzeigt.
A30: Das zweite Diagramm soll ein kombiniertes Säulen und Liniendiagramm sein: Umsatz/Stück als Säulen und Retourenquote als Linie. Dazu sind zwei Y-Achsen zu verwenden

Sheet Aufgabe3
A1: In dieser Aufgabe geht es darum, einige Funktionen auf Listen anzuwenden. Dazu gehören z.B. die Median-Funktion oder auch der SVERWEIS.
A2: Beantworte dazu einfach die Fragen, indem du eine Formel in die rot umrahmten Zellen einträgst.
A4: Verkäufer | B4: Datum | C4: Produkte | D4: Umsatz | E4: Region
A5: Hr. Sommer | B5: 43473 | C5: 6 | D5: 2976.66 | E5: Ost
A6: Fr. Frühling | B6: 43480 | C6: 4 | D6: 209.68 | E6: West | G6: Was ist der Median der Produkte? | M6: (Hint: Wenn du in der einen Bereich mit Zahlen markierst, werden dir unter anderem auch diese Werte in der Fußzeile angegeben, mit Rechtsklick kannst du einstellen, welche Werte angezeigt werden sollen)
A7: Hr. Sommer | B7: 43481 | C7: 10 | D7: 58.13 | E7: Süd | G7: Was ist der Mittelwert der Produkte?
A8: Hr. Herbst | B8: 43492 | C8: 2 | D8: 195.85 | E8: Nord
A9: Fr. Winter | B9: 43494 | C9: 3 | D9: 11.05 | E9: Nord | G9: Was ist der Median des Umsatzes?
A10: Fr. Winter | B10: 43499 | C10: 14 | D10: 762.27 | E10: Ost | G10: Was ist der Mittelwert des Umsatzes?
A11: Hr. Herbst | B11: 43502 | C11: 21 | D11: 1721.39 | E11: West
A12: Fr. Frühling | B12: 43503 | C12: 3 | D12: 164.45 | E12: Ost | G12: Wie viel Produkte wurden minimal verkauft?
A13: Hr. Sommer | B13: 43504 | C13: 6 | D13: 468.82 | E13: Süd | G13: Wie viel Produkte wurden maximal verkauft?
A14: Hr. Herbst | B14: 43508 | C14: 17 | D14: 1448.97 | E14: Nord
A15: Fr. Winter | B15: 43510 | C15: 12 | D15: 682.76 | E15: Ost | G15: Wie viele Umsatz hat Fr. Winter erzielt?
A16: Hr. Sommer | B16: 43513 | C16: 9 | D16: 329.7 | E16: Süd | G16: Wie viele Umsatz hat Fr. Frühling erzielt?
A17: Fr. Frühling | B17: 43520 | C17: 1 | D17: 42.13 | E17: Nord | G17: Wie viele Umsatz hat Hr. Sommer erzielt?
A18: Hr. Herbst | B18: 43524 | C18: 19 | D18: 209.79 | E18: Nord | G18: Wie viele Umsatz hat Hr. Herbst erzielt?
A19: Fr. Frühling | B19: 43527 | C19: 8 | D19: 449.78 | E19: Ost
A20: Fr. Winter | B20: 43529 | C20: 16 | D20: 1071.72 | E20: Süd
A21: Hr. Sommer | B21: 43530 | C21: 5 | D21: 199.09 | E21: West | G21: Verwende die bedingte Formatierung, um die Spalten Produkte und Umsatz mit der Grün-Gelb-Rot skala schnell und einfach zu visualisieren.
A22: Hr. Sommer | B22: 43536 | C22: 4 | D22: 69.95 | E22: West
A23: Hr. Herbst | B23: 43539 | C23: 22 | D23: 811.46 | E23: Nord
A24: Hr. Sommer | B24: 43542 | C24: 19 | D24: 1619.97 | E24: West
A25: Fr. Frühling | B25: 43544 | C25: 9 | D25: 248.85 | E25: Ost
A26: Fr. Winter | B26: 43546 | C26: 11 | D26: 974.85 | E26: Süd
A27: Hr. Herbst | B27: 43551 | C27: 18 | D27: 253.08 | E27: Süd
A28: Hr. Herbst | B28: 43552 | C28: 13 | D28: 554.87 | E28: Nord
A29: Fr. Frühling | B29: 43553 | C29: 7 | D29: 501.05 | E29: Ost
A30: Fr. Winter | B30: 43555 | C30: 2 | D30: 51.6 | E30: West

Sheet Aufgabe3 Lösung
A4: Verkäufer | B4: Datum | C4: Produkte | D4: Umsatz | E4: Region
A5: Hr. Sommer | B5: 43473 | C5: 6 | D5: 2976.66 | E5: Ost
A6: Fr. Frühling | B6: 43480 | C6: 4 | D6: 209.68 | E6: West | G6: Was ist der Median der Produkte? | K6: =MEDIAN(C5:C30) -> 9 | O6: Wann war das? | S6: =INDEX($B$5:$B$30,MATCH($K$12,$C$5:$C$30,0)) -> 43520
A7: Hr. Sommer | B7: 43481 | C7: 10 | D7: 58.13 | E7: Süd | G7: Was ist der Mittelwert der Produkte? | K7: =AVERAGE(C5:C30) -> 10.038462 | O7: Wie viel Umsatz wurde an diesem Tag erzielt? | S7: =VLOOKUP($K$13,$C$5:$D$30,2,) -> 811.46
A8: Hr. Herbst | B8: 43492 | C8: 2 | D8: 195.85 | E8: Nord
A9: Fr. Winter | B9: 43494 | C9: 3 | D9: 11.05 | E9: Nord | G9: Was ist der Median des Umsatzes? | K9: =MEDIAN(D5:D30) -> 389.74 | O9: Welcher Verkäufer hat die meisten Produkte verkauft? | T9: =INDEX($A$5:$A$30,MATCH($K$13,$C$5:$C$30,0)) -> Hr. Herbst
A10: Fr. Winter | B10: 43499 | C10: 14 | D10: 762.27 | E10: Ost | G10: Was ist der Mittelwert des Umsatzes? | K10: =AVERAGE(D5:D30) -> 618.76615 | O10: Wie hoch ist der größte Gesamtumsatz einer Region? | T10: =MAX(SUMIFS($D$5:$D$30,$E$5:$E$30,"Ost"),SUMIFS($D$5:$D$30,$E$5:$E$30,"Süd"),SUMIFS($D$5:$D$30,$E$5:$E$30,"Nord"),SUMIFS($D$5:$D$30,$E$5:$E$30,"West")) -> 5785.82
A11: Hr. Herbst | B11: 43502 | C11: 21 | D11: 1721.39 | E11: West
A12: Fr. Frühling | B12: 43503 | C12: 3 | D12: 164.45 | E12: Ost | G12: Wie viel Produkte wurden minimal verkauft? | K12: =MIN(C5:C30) -> 1
A13: Hr. Sommer | B13: 43504 | C13: 6 | D13: 468.82 | E13: Süd | G13: Wie viel Produkte wurden maximal verkauft? | K13: =MAX(C5:C30) -> 22
A14: Hr. Herbst | B14: 43508 | C14: 17 | D14: 1448.97 | E14: Nord
A15: Fr. Winter | B15: 43510 | C15: 12 | D15: 682.76 | E15: Ost | G15: Wie viele Umsatz hat Fr. Winter erzielt? | K15: =SUMIFS(D5:D30,A5:A30,"Fr. Winter") -> 3554.25
A16: Hr. Sommer | B16: 43513 | C16: 9 | D16: 329.7 | E16: Süd | G16: Wie viele Umsatz hat Fr. Frühling erzielt? | K16: =SUMIFS(D5:D30,A5:A30,"Fr. Frühling") -> 1615.94
A17: Fr. Frühling | B17: 43520 | C17: 1 | D17: 42.13 | E17: Nord | G17: Wie viele Umsatz hat Hr. Sommer erzielt? | K17: =SUMIFS(D5:D30,A5:A30,"Hr. Sommer") -> 5722.32
A18: Hr. Herbst | B18: 43524 | C18: 19 | D18: 209.79 | E18: Nord | G18: Wie viele Umsatz hat Hr. Herbst erzielt? | K18: =SUMIFS(D5:D30,A5:A30,"Hr. Herbst") -> 5195.41
A19: Fr. Frühling | B19: 43527 | C19: 8 | D19: 449.78 | E19: Ost
A20: Fr. Winter | B20: 43529 | C20: 16 | D20: 1071.72 | E20: Süd | G20: Wann war das? | K20: =INDEX($B$5:$B$30,MATCH($K$12,$C$5:$C$30,0)) -> 43520
A21: Hr. Sommer | B21: 43530 | C21: 5 | D21: 199.09 | E21: West | G21: Wie viel Umsatz wurde an diesem Tag erzielt? | K21: =VLOOKUP($K$13,$C$5:$D$30,2,) -> 811.46
A22: Hr. Sommer | B22: 43536 | C22: 4 | D22: 69.95 | E22: West
A23: Hr. Herbst | B23: 43539 | C23: 22 | D23: 811.46 | E23: Nord | G23: Welcher Verkäufer hat die meisten Produkte verkauft? | L23: =INDEX($A$5:$A$30,MATCH($K$13,$C$5:$C$30,0)) -> Hr. Herbst
A24: Hr. Sommer | B24: 43542 | C24: 19 | D24: 1619.97 | E24: West | G24: Wie hoch ist der größte Gesamtumsatz einer Region? | L24: =MAX(SUMIFS($D$5:$D$30,$E$5:$E$30,"Ost"),SUMIFS($D$5:$D$30,$E$5:$E$30,"Süd"),SUMIFS($D$5:$D$30,$E$5:$E$30,"Nord"),SUMIFS($D$5:$D$30,$E$5:$E$30,"West")) -> 5785.82
A25: Fr. Frühling | B25: 43544 | C25: 9 | D25: 248.85 | E25: Ost
A26: Fr. Winter | B26: 43546 | C26: 11 | D26: 974.85 | E26: Süd | G26: Verwende die bedingte Formatierung, um die Spalten Produkte und Umsatz mit der Grün-Gelb-Rot skala schnell und einfach zu visualisieren.
A27: Hr. Herbst | B27: 43551 | C27: 18 | D27: 253.08 | E27: Süd
A28: Hr. Herbst | B28: 43552 | C28: 13 | D28: 554.87 | E28: Nord
A29: Fr. Frühling | B29: 43553 | C29: 7 | D29: 501.05 | E29: Ost
A30: Fr. Winter | B30: 43555 | C30: 2 | D30: 51.6 | E30: West

Sheet Aufgabe4
B1: Kollege A | C1: Kollege B | D1: Kollege C
A2: max. Raumzahl | B2: 50 | C2: 200 | D2: 72
A3: braucht Frühstück | B3: ja | C3: ja | D3: ja
A4: braucht Parkhaus | B4: nein | C4: nein | D4: ja
A5: bleibt Tage | B5: 7 | C5: 8 | D5: 2
A6: Reisebudget | B6: 622 | C6: 1243 | D6: 398

Sheet Aufgabe5
A1: Deine Kollegin plant einen Besuch für Kollegen eines anderen Standorts und hat anscheinend zu viel Zeit. Deswegen hat sie eine Liste mit Hotels und deren Eigenschaften erstellt.
A3: Um die Tabelle zu bearbeiten, musst du den Schutz des Blattes aufheben. Die Kollegin hat das unsichere und einfallslose, aber immerhin leicht zu merkende Passwort "bonprix" gewählt.
A4: Für 5 verschiedene Kolleginnen hat sie Ansprüche an die Hotels gesammelt und diese in dem Tabellenblatt Aufgabe4 notiert.
A6: Zunächst sollst du für jedes Hotel für eine bis zu acht Nächten den Gesamtpreis ausrechnen.
A7: Manche Hotels bieten bei einer Verweildauer von sieben oder mehr Tagen einen Rabatt in Höhe des Preises einer Nacht an. Dieses sollte mit berechnet werden.
A9: Anschließend sollst du in der unteren Hotel-Liste auswerten, welche Hotels für jede Kollegin in Frage kommen. Nutze dazu die WENN-Funktion und die UND-Funktion und beziehe dich direkt auf die Werte aus dem Blatt "Aufgabe4".
A10: Um es dir einfacher zu machen, denke an relative und absolute Bezüge.
I11: Preis für Nächte
A12: Hotelname | B12: Zimmer | C12: Preis per Nacht | D12: Rabatt ab 7 Tagen | E12: Frühstück | F12: Parkhaus | G12: Sterne | H12: WLAN | I12: 1 | J12: 2 | K12: 3 | L12: 4 | M12: 5 | N12: 6 | O12: 7 | P12: 8
A13: ABC-Hotel | B13: 128 | C13: 45 | D13: ja | E13: nein | F13: nein | G13: 3 | H13: ja
A14: Hotel de Luxe | B14: 72 | C14: 263 | D14: nein | E14: ja | F14: ja | G14: 5 | H14: ja
A15: Hotel ohne Namen | B15: 44 | C15: 52 | D15: ja | E15: nein | F15: ja | G15: 3 | H15: ja
A16: Hotel am Hafen | B16: 45 | C16: 78 | D16: ja | E16: ja | F16: nein | G16: 3 | H16: ja
A17: Alsterblick Hotel | B17: 38 | C17: 126 | D17: nein | E17: ja | F17: ja | G17: 5 | H17: ja
A18: Design Hotel lorem ipsum | B18: 63 | C18: 110 | D18: nein | E18: ja | F18: ja | G18: 4 | H18: ja
A19: Zum goldenen Geier | B19: 24 | C19: 89 | D19: nein | E19: ja | F19: nein | G19: 4 | H19: ja
A20: Cheap Cheap - Bird Hotel | B20: 160 | C20: 23 | D20: ja | E20: nein | F20: nein | G20: 2 | H20: nein
A21: All You Can Sleep Hotel | B21: 106 | C21: 62 | D21: ja | E21: ja | F21: ja | G21: 3 | H21: ja
A22: Excellence Hotel Hamburg | B22: 68 | C22: 198 | D22: nein | E22: ja | F22: ja | G22: 5 | H22: ja
A25: Hotelname | B25: =Aufgabe4!B1 -> Kollege A | C25: =Aufgabe4!C1 -> Kollege B | D25: =Aufgabe4!D1 -> Kollege C
A26: ABC-Hotel
A27: Hotel de Luxe
A28: Hotel ohne Namen
A29: Hotel am Hafen
A30: Alsterblick Hotel
A31: Design Hotel lorem ipsum
A32: Zum goldenen Geier
A33: Cheap Cheap - Bird Hotel
A34: All You Can Sleep Hotel
A35: Excellence Hotel Hamburg

Sheet Aufgabe5 Lösung
A1: Deine Kollegin plant einen Besuch für Kollegen eines anderen Standorts und hat anscheinend zu viel Zeit. Deswegen hat sie eine Liste mit Hotels und deren Eigenschaften erstellt.
A4: Um die Tabelle zu bearbeiten, musst du den Schutz des Blattes aufheben. Die Kollegin hat das unsichere und einfallslose, aber immerhin leicht zu merkende Passwort "bonprix" gewählt. | O4: Wenn, und
A5: Für 5 verschiedene Kolleginnen hat sie Ansprüche an die Hotels gesammelt und diese in dem Tabellenblatt Aufgabe4 notiert.
A7: Zunächst sollst du für jedes Hotel für eine bis zu acht Nächten den Gesamtpreis ausrechnen.
A8: Manche Hotels bieten bei einer Verweildauer von sieben oder mehr Tagen einen Rabatt in Höhe des Preises einer Nacht an. Dieses sollte mit berechnet werden.
A10: Anschließend sollst du in der unteren Hotel-Liste auswerten, welche Hotels für jede Kollegin in Frage kommen. Nutze dazu die Wenn funktion und die und funktion und beziehe dich direkt auf die Werte aus dem Blatt "Aufgabe4".
I12: Preis für Nächte
A13: Hotelname | B13: Zimmer | C13: Preis per Nacht | D13: Rabatt ab 7 Tagen | E13: Frühstück | F13: Parkhaus | G13: Sterne | H13: WLAN | I13: 1 | J13: 2 | K13: 3 | L13: 4 | M13: 5 | N13: 6 | O13: 7 | P13: 8
A14: ABC-Hotel | B14: 128 | C14: 45 | D14: ja | E14: nein | F14: nein | G14: 3 | H14: ja | I14: =I$13*$C14 -> 45 | J14: =J$13*$C14 -> 90 | K14: =K$13*$C14 -> 135 | L14: =L$13*$C14 -> 180 | M14: =M$13*$C14 -> 225 | N14: =N$13*$C14 -> 270 | O14: =IF($D14="ja",(O$13-1)*$C14,O$13*$C14) -> 270 | P14: =IF($D14="ja",(P$13-1)*$C14,P$13*$C14) -> 315
A15: Hotel de Luxe | B15: 72 | C15: 263 | D15: nein | E15: ja | F15: ja | G15: 5 | H15: ja | I15: =I$13*$C15 -> 263 | J15: =J$13*$C15 -> 526 | K15: =K$13*$C15 -> 789 | L15: =L$13*$C15 -> 1052 | M15: =M$13*$C15 -> 1315 | N15: =N$13*$C15 -> 1578 | O15: =IF($D15="ja",(O$13-1)*$C15,O$13*$C15) -> 1841 | P15: =IF($D15="ja",(P$13-1)*$C15,P$13*$C15) -> 2104
A16: Hotel ohne Namen | B16: 44 | C16: 52 | D16: ja | E16: nein | F16: ja | G16: 3 | H16: ja | I16: =I$13*$C16 -> 52 | J16: =J$13*$C16 -> 104 | K16: =K$13*$C16 -> 156 | L16: =L$13*$C16 -> 208 | M16: =M$13*$C16 -> 260 | N16: =N$13*$C16 -> 312 | O16: =IF($D16="ja",(O$13-1)*$C16,O$13*$C16) -> 312 | P16: =IF($D16="ja",(P$13-1)*$C16,P$13*$C16) -> 364
A17: Hotel am Hafen | B17: 45 | C17: 78 | D17: ja | E17: ja | F17: nein | G17: 3 | H17: ja | I17: =I$13*$C17 -> 78 | J17: =J$13*$C17 -> 156 | K17: =K$13*$C17 -> 234 | L17: =L$13*$C17 -> 312 | M17: =M$13*$C17 -> 390 | N17: =N$13*$C17 -> 468 | O17: =IF($D17="ja",(O$13-1)*$C17,O$13*$C17) -> 468 | P17: =IF($D17="ja",(P$13-1)*$C17,P$13*$C17) -> 546
A18: Alsterblick Hotel | B18: 38 | C18: 126 | D18: nein | E18: ja | F18: ja | G18: 5 | H18: ja | I18: =I$13*$C18 -> 126 | J18: =J$13*$C18 -> 252 | K18: =K$13*$C18 -> 378 | L18: =L$13*$C18 -> 504 | M18: =M$13*$C18 -> 630 | N18: =N$13*$C18 -> 756 | O18: =IF($D18="ja",(O$13-1)*$C18,O$13*$C18) -> 882 | P18: =IF($D18="ja",(P$13-1)*$C18,P$13*$C18) -> 1008
A19: Design Hotel lorem ipsum | B19: 63 | C19: 110 | D19: nein | E19: ja | F19: ja | G19: 4 | H19: ja | I19: =I$13*$C19 -> 110 | J19: =J$13*$C19 -> 220 | K19: =K$13*$C19 -> 330 | L19: =L$13*$C19 -> 440 | M19: =M$13*$C19 -> 550 | N19: =N$13*$C19 -> 660 | O19: =IF($D19="ja",(O$13-1)*$C19,O$13*$C19) -> 770 | P19: =IF($D19="ja",(P$13-1)*$C19,P$13*$C19) -> 880
A20: Zum goldenen Geier | B20: 24 | C20: 89 | D20: nein | E20: ja | F20: nein | G20: 4 | H20: ja | I20: =I$13*$C20 -> 89 | J20: =J$13*$C20 -> 178 | K20: =K$13*$C20 -> 267 | L20: =L$13*$C20 -> 356 | M20: =M$13*$C20 -> 445 | N20: =N$13*$C20 -> 534 | O20: =IF($D20="ja",(O$13-1)*$C20,O$13*$C20) -> 623 | P20: =IF($D20="ja",(P$13-1)*$C20,P$13*$C20) -> 712
A21: Cheap Cheap - Bird Hotel | B21: 160 | C21: 23 | D21: ja | E21: nein | F21: nein | G21: 2 | H21: nein | I21: =I$13*$C21 -> 23 | J21: =J$13*$C21 -> 46 | K21: =K$13*$C21 -> 69 | L21: =L$13*$C21 -> 92 | M21: =M$13*$C21 -> 115 | N21: =N$13*$C21 -> 138 | O21: =IF($D21="ja",(O$13-1)*$C21,O$13*$C21) -> 138 | P21: =IF($D21="ja",(P$13-1)*$C21,P$13*$C21) -> 161
A22: All You Can Sleep Hotel | B22: 106 | C22: 62 | D22: ja | E22: ja | F22: ja | G22: 3 | H22: ja | I22: =I$13*$C22 -> 62 | J22: =J$13*$C22 -> 124 | K22: =K$13*$C22 -> 186 | L22: =L$13*$C22 -> 248 | M22: =M$13*$C22 -> 310 | N22: =N$13*$C22 -> 372 | O22: =IF($D22="ja",(O$13-1)*$C22,O$13*$C22) -> 372 | P22: =IF($D22="ja",(P$13-1)*$C22,P$13*$C22) -> 434
A23: Excellence Hotel Hamburg | B23: 68 | C23: 198 | D23: nein | E23: ja | F23: ja | G23: 5 | H23: ja | I23: =I$13*$C23 -> 198 | J23: =J$13*$C23 -> 396 | K23: =K$13*$C23 -> 594 | L23: =L$13*$C23 -> 792 | M23: =M$13*$C23 -> 990 | N23: =N$13*$C23 -> 1188 | O23: =IF($D23="ja",(O$13-1)*$C23,O$13*$C23) -> 1386 | P23: =IF($D23="ja",(P$13-1)*$C23,P$13*$C23) -> 1584
A26: Hotelname | B26: =Aufgabe4!B1 -> Kollege A | C26: =Aufgabe4!C1 -> Kollege B | D26: =Aufgabe4!D1 -> Kollege C
A27: ABC-Hotel | B27: =IF(AND($B14<Aufgabe4!B$2,$E14=Aufgabe4!B$3,$O14<Aufgabe4!B$6),$O14,"passt nicht") -> passt nicht | C27: =IF(AND($B14<Aufgabe4!$C$2,$E14=Aufgabe4!$C$3,P14<Aufgabe4!$C$6),P14,"passt nicht") -> passt nicht | D27: =IF(AND($B14<Aufgabe4!$D$2,E14=Aufgabe4!$D$3,F14=Aufgabe4!$D$4,J14<Aufgabe4!$D$6),J14,"passt nicht") -> passt nicht
A28: Hotel de Luxe | B28: =IF(AND($B15<Aufgabe4!B$2,$E15=Aufgabe4!B$3,$O15<Aufgabe4!B$6),$O15,"passt nicht") -> passt nicht | C28: =IF(AND($B15<Aufgabe4!$C$2,$E15=Aufgabe4!$C$3,P15<Aufgabe4!$C$6),P15,"passt nicht") -> passt nicht | D28: =IF(AND($B15<Aufgabe4!$D$2,E15=Aufgabe4!$D$3,F15=Aufgabe4!$D$4,J15<Aufgabe4!$D$6),J15,"passt nicht") -> passt nicht
A29: Hotel ohne Namen | B29: =IF(AND($B16<Aufgabe4!B$2,$E16=Aufgabe4!B$3,$O16<Aufgabe4!B$6),$O16,"passt nicht") -> passt nicht | C29: =IF(AND($B16<Aufgabe4!$C$2,$E16=Aufgabe4!$C$3,P16<Aufgabe4!$C$6),P16,"passt nicht") -> passt nicht | D29: =IF(AND($B16<Aufgabe4!$D$2,E16=Aufgabe4!$D$3,F16=Aufgabe4!$D$4,J16<Aufgabe4!$D$6),J16,"passt nicht") -> passt nicht
A30: Hotel am Hafen | B30: =IF(AND($B17<Aufgabe4!B$2,$E17=Aufgabe4!B$3,$O17<Aufgabe4!B$6),$O17,"passt nicht") -> 468 | C30: =IF(AND($B17<Aufgabe4!$C$2,$E17=Aufgabe4!$C$3,P17<Aufgabe4!$C$6),P17,"passt nicht") -> 546 | D30: =IF(AND($B17<Aufgabe4!$D$2,E17=Aufgabe4!$D$3,F17=Aufgabe4!$D$4,J17<Aufgabe4!$D$6),J17,"passt nicht") -> passt nicht
A31: Alsterblick Hotel | B31: =IF(AND($B18<Aufgabe4!B$2,$E18=Aufgabe4!B$3,$O18<Aufgabe4!B$6),$O18,"passt nicht") -> passt nicht | C31: =IF(AND($B18<Aufgabe4!$C$2,$E18=Aufgabe4!$C$3,P18<Aufgabe4!$C$6),P18,"passt nicht") -> 1008 | D31: =IF(AND($B18<Aufgabe4!$D$2,E18=Aufgabe4!$D$3,F18=Aufgabe4!$D$4,J18<Aufgabe4!$D$6),J18,"passt nicht") -> 252
A32: Design Hotel lorem ipsum | B32: =IF(AND($B19<Aufgabe4!B$2,$E19=Aufgabe4!B$3,$O19<Aufgabe4!B$6),$O19,"passt nicht") -> passt nicht | C32: =IF(AND($B19<Aufgabe4!$C$2,$E19=Aufgabe4!$C$3,P19<Aufgabe4!$C$6),P19,"passt nicht") -> 880 | D32: =IF(AND($B19<Aufgabe4!$D$2,E19=Aufgabe4!$D$3,F19=Aufgabe4!$D$4,J19<Aufgabe4!$D$6),J19,"passt nicht") -> 220
A33: Zum goldenen Geier | B33: =IF(AND($B20<Aufgabe4!B$2,$E20=Aufgabe4!B$3,$O20<Aufgabe4!B$6),$O20,"passt nicht") -> passt nicht | C33: =IF(AND($B20<Aufgabe4!$C$2,$E20=Aufgabe4!$C$3,P20<Aufgabe4!$C$6),P20,"passt nicht") -> 712 | D33: =IF(AND($B20<Aufgabe4!$D$2,E20=Aufgabe4!$D$3,F20=Aufgabe4!$D$4,J20<Aufgabe4!$D$6),J20,"passt nicht") -> passt nicht
A34: Cheap Cheap - Bird Hotel | B34: =IF(AND($B21<Aufgabe4!B$2,$E21=Aufgabe4!B$3,$O21<Aufgabe4!B$6),$O21,"passt nicht") -> passt nicht | C34: =IF(AND($B21<Aufgabe4!$C$2,$E21=Aufgabe4!$C$3,P21<Aufgabe4!$C$6),P21,"passt nicht") -> passt nicht | D34: =IF(AND($B21<Aufgabe4!$D$2,E21=Aufgabe4!$D$3,F21=Aufgabe4!$D$4,J21<Aufgabe4!$D$6),J21,"passt nicht") -> passt nicht
A35: All You Can Sleep Hotel | B35: =IF(AND($B22<Aufgabe4!B$2,$E22=Aufgabe4!B$3,$O22<Aufgabe4!B$6),$O22,"passt nicht") -> passt nicht | C35: =IF(AND($B22<Aufgabe4!$C$2,$E22=Aufgabe4!$C$3,P22<Aufgabe4!$C$6),P22,"passt nicht") -> 434 | D35: =IF(AND($B22<Aufgabe4!$D$2,E22=Aufgabe4!$D$3,F22=Aufgabe4!$D$4,J22<Aufgabe4!$D$6),J22,"passt nicht") -> passt nicht
A36: Excellence Hotel Hamburg | B36: =IF(AND($B23<Aufgabe4!B$2,$E23=Aufgabe4!B$3,$O23<Aufgabe4!B$6),$O23,"passt nicht") -> passt nicht | C36: =IF(AND($B23<Aufgabe4!$C$2,$E23=Aufgabe4!$C$3,P23<Aufgabe4!$C$6),P23,"passt nicht") -> passt nicht | D36: =IF(AND($B23<Aufgabe4!$D$2,E23=Aufgabe4!$D$3,F23=Aufgabe4!$D$4,J23<Aufgabe4!$D$6),J23,"passt nicht") -> 396

Sheet AufgabeErsatz
A1: Country | B1: Campaign ID | C1: Campaign Name | D1: Day | E1: Currency | F1: Views | G1: CTR | H1: Clicks | I1: CPC | J1: ECPM | K1: Sales | L1: Sales ND | M1: CVR | N1: Revenue | O1: Avg. Cart | P1: Cost | Q1: COS
A2: Bonprix Germany | B2: 28644 | C2: Facebook | D2: 42552 | E2: EUR | F2: 29645 | G2: 0.010586974 | H2: 546 | I2: 1.4199999 | J2: 15.033502 | K2: 35 | L2: 42 | M2: 0.12236287 | N2: 5182.9889 | O2: 89.361878 | P2: 673.07995 | Q2: 0.12986328
A3: Bonprix Germany | B3: 28644 | C3: Facebook | D3: 42553 | E3: EUR | F3: 5181 | G3: 0.0094367121 | H3: 263 | I3: 1.4199999 | J3: 13.40013 | K3: 49 | L3: 55 | M3: 0.073359073 | N3: 3522.4739 | O3: 92.696681 | P3: 735.55996 | Q3: 0.20881914
A4: Bonprix Germany | B4: 28644 | C4: Facebook | D4: 42554 | E4: EUR | F4: 37364 | G4: 0.007871621 | H4: 415 | I4: 1.42 | J4: 11.177702 | K4: 96 | L4: 57 | M4: 0.095454545 | N4: 4149.6238 | O4: 98.800567 | P4: 624.80001 | Q4: 0.15056787
A5: Bonprix Germany | B5: 28644 | C5: Facebook | D5: 42555 | E5: EUR | F5: 63380 | G5: 0.0080906149 | H5: 594 | I5: 1.42 | J5: 11.488673 | K5: 34 | L5: 47 | M5: 0.071604938 | N5: 2762.9169 | O5: 95.272995 | P5: 575.1 | Q5: 0.20814959
A6: Bonprix Germany | B6: 28644 | C6: Facebook | D6: 42556 | E6: EUR | F6: 68629 | G6: 0.0089567408 | H6: 327 | I6: 1.3929551 | J6: 12.476338 | K6: 55 | L6: 39 | M6: 0.04964539 | N6: 1333.9528 | O6: 63.521562 | P6: 589.22 | Q6: 0.44170978
A7: Bonprix Germany | B7: 28644 | C7: Facebook | D7: 42557 | E7: EUR | F7: 47953 | G7: 0.0096592142 | H7: 538 | I7: 1.38 | J7: 13.329715 | K7: 70 | L7: 42 | M7: 0.058426966 | N7: 2028.9567 | O7: 78.036796 | P7: 614.09999 | Q7: 0.30266786
A8: Bonprix Germany | B8: 28644 | C8: Facebook | D8: 42558 | E8: EUR | F8: 11584 | G8: 0.0095642933 | H8: 352 | I8: 1.38 | J8: 13.198725 | K8: 84 | L8: 40 | M8: 0.084795322 | N8: 4286.4552 | O8: 147.8088 | P8: 471.96 | Q8: 0.11010497
A9: Bonprix Germany | B9: 28644 | C9: Facebook | D9: 42559 | E9: EUR | F9: 55098 | G9: 0.010014525 | H9: 402 | I9: 1.38 | J9: 13.820045 | K9: 57 | L9: 59 | M9: 0.10178117 | N9: 3998.79 | O9: 99.969751 | P9: 542.34001 | Q9: 0.13562603
A10: Bonprix Germany | B10: 28644 | C10: Facebook | D10: 42560 | E10: EUR | F10: 1899 | G10: 0.0092178642 | H10: 158 | I10: 1.38 | J10: 12.720653 | K10: 83 | L10: 51 | M10: 0.0825 | N10: 2566.2113 | O10: 77.76398 | P10: 552 | Q10: 0.21510309
A11: Bonprix Germany | B11: 28644 | C11: Facebook | D11: 42561 | E11: EUR | F11: 15449 | G11: 0.0094737098 | H11: 316 | I11: 1.349563 | J11: 12.785368 | K11: 29 | L11: 27 | M11: 0.043701799 | N11: 1910.8394 | O11: 112.40231 | P11: 524.98002 | Q11: 0.27473791
A12: Bonprix Germany | B12: 28644 | C12: Facebook | D12: 42562 | E12: EUR | F12: 2118 | G12: 0.0094535183 | H12: 415 | I12: 1.3401928 | J12: 12.669537 | K12: 92 | L12: 54 | M12: 0.074698795 | N12: 2882.1852 | O12: 92.973717 | P12: 556.18001 | Q12: 0.19297164
A13: Bonprix Germany | B13: 28644 | C13: Facebook | D13: 42563 | E13: EUR | F13: 12114 | G13: 0.0084337051 | H13: 552 | I13: 1.3469795 | J13: 11.360028 | K13: 15 | L13: 43 | M13: 0.06744868 | N13: 2284.0781 | O13: 99.307743 | P13: 459.32 | Q13: 0.20109645
... A1271: Bonprix Germany | B1271: 937733 | C1271: Video | D1271: 42678 | E1271: EUR | F1271: 14352 | G1271: 0.010208611 | H1271: 190 | I1271: 0.67260873 | J1271: 6.8664007 | K1271: 87 | L1271: 1 | M1271: 0.043478261 | N1271: 117.44432 | O1271: 117.44432 | P1271: 15.470001 | Q1271: 0.131722

Sheet AufgabeErsatz Lösung
A1: Country | B1: Campaign ID | C1: Campaign Name | D1: Day | E1: Currency | F1: Views | G1: CTR | H1: Clicks | I1: CPC | J1: ECPM | K1: Sales | L1: Sales ND | M1: CVR | N1: Revenue | O1: Avg. Cart | P1: Cost | Q1: COS
A2: Bonprix Germany | B2: 28644 | C2: Facebook | D2: 42552 | E2: EUR | F2: 29645 | G2: 0.010586974 | H2: 546 | I2: 1.4199999 | J2: 15.033502 | K2: 35 | L2: 42 | M2: 0.12236287 | N2: 5182.9889 | O2: 89.361878 | P2: 673.07995 | Q2: 0.12986328
A3: Bonprix Germany | B3: 28644 | C3: Facebook | D3: 42553 | E3: EUR | F3: 5181 | G3: 0.0094367121 | H3: 263 | I3: 1.4199999 | J3: 13.40013 | K3: 49 | L3: 55 | M3: 0.073359073 | N3: 3522.4739 | O3: 92.696681 | P3: 735.55996 | Q3: 0.20881914
A4: Bonprix Germany | B4: 28644 | C4: Facebook | D4: 42554 | E4: EUR | F4: 37364 | G4: 0.007871621 | H4: 415 | I4: 1.42 | J4: 11.177702 | K4: 96 | L4: 57 | M4: 0.095454545 | N4: 4149.6238 | O4: 98.800567 | P4: 624.80001 | Q4: 0.15056787
A5: Bonprix Germany | B5: 28644 | C5: Facebook | D5: 42555 | E5: EUR | F5: 63380 | G5: 0.0080906149 | H5: 594 | I5: 1.42 | J5: 11.488673 | K5: 34 | L5: 47 | M5: 0.071604938 | N5: 2762.9169 | O5: 95.272995 | P5: 575.1 | Q5: 0.20814959
A6: Bonprix Germany | B6: 28644 | C6: Facebook | D6: 42556 | E6: EUR | F6: 68629 | G6: 0.0089567408 | H6: 327 | I6: 1.3929551 | J6: 12.476338 | K6: 55 | L6: 39 | M6: 0.04964539 | N6: 1333.9528 | O6: 63.521562 | P6: 589.22 | Q6: 0.44170978
A7: Bonprix Germany | B7: 28644 | C7: Facebook | D7: 42557 | E7: EUR | F7: 47953 | G7: 0.0096592142 | H7: 538 | I7: 1.38 | J7: 13.329715 | K7: 70 | L7: 42 | M7: 0.058426966 | N7: 2028.9567 | O7: 78.036796 | P7: 614.09999 | Q7: 0.30266786
A8: Bonprix Germany | B8: 28644 | C8: Facebook | D8: 42558 | E8: EUR | F8: 11584 | G8: 0.0095642933 | H8: 352 | I8: 1.38 | J8: 13.198725 | K8: 84 | L8: 40 | M8: 0.084795322 | N8: 4286.4552 | O8: 147.8088 | P8: 471.96 | Q8: 0.11010497
A9: Bonprix Germany | B9: 28644 | C9: Facebook | D9: 42559 | E9: EUR | F9: 55098 | G9: 0.010014525 | H9: 402 | I9: 1.38 | J9: 13.820045 | K9: 57 | L9: 59 | M9: 0.10178117 | N9: 3998.79 | O9: 99.969751 | P9: 542.34001 | Q9: 0.13562603
A10: Bonprix Germany | B10: 28644 | C10: Facebook | D10: 42560 | E10: EUR | F10: 1899 | G10: 0.0092178642 | H10: 158 | I10: 1.38 | J10: 12.720653 | K10: 83 | L10: 51 | M10: 0.0825 | N10: 2566.2113 | O10: 77.76398 | P10: 552 | Q10: 0.21510309
A11: Bonprix Germany | B11: 28644 | C11: Facebook | D11: 42561 | E11: EUR | F11: 15449 | G11: 0.0094737098 | H11: 316 | I11: 1.349563 | J11: 12.785368 | K11: 29 | L11: 27 | M11: 0.043701799 | N11: 1910.8394 | O11: 112.40231 | P11: 524.98002 | Q11: 0.27473791
A12: Bonprix Germany | B12: 28644 | C12: Facebook | D12: 42562 | E12: EUR | F12: 2118 | G12: 0.0094535183 | H12: 415 | I12: 1.3401928 | J12: 12.669537 | K12: 92 | L12: 54 | M12: 0.074698795 | N12: 2882.1852 | O12: 92.973717 | P12: 556.18001 | Q12: 0.19297164
A13: Bonprix Germany | B13: 28644 | C13: Facebook | D13: 42563 | E13: EUR | F13: 12114 | G13: 0.0084337051 | H13: 552 | I13: 1.3469795 | J13: 11.360028 | K13: 15 | L13: 43 | M13: 0.06744868 | N13: 2284.0781 | O13: 99.307743 | P13: 459.32 | Q13: 0.20109645
... A1271: Bonprix Germany | B1271: 937733 | C1271: Video | D1271: 42678 | E1271: EUR | F1271: 14352 | G1271: 0.010208611 | H1271: 190 | I1271: 0.67260873 | J1271: 6.8664007 | K1271: 87 | L1271: 1 | M1271: 0.043478261 | N1271: 117.44432 | O1271: 117.44432 | P1271: 15.470001 | Q1271: 0.131722

Sheet Aufgabe6
A1: Hier darfst du nun noch deiner "Kreativität" freien Lauf lassen. Gefordert sind verschiedene Diagrammtypen. Rechts siehst du die Mustervorlage.
A2: Die Diagramme sollten (theoretisch, du musst die jetzt nicht ausdrucken) ausgedruckt werden. Die Tabellen daneben sollen nicht gedruckt werden.
A3: Lege also bitte noch den Druckbereich fest und erstelle die Diagramme in den jeweils farbig hinterlegten Bereichen
A5: Datum | B5: Modell A | C5: Modell B | D5: Modell C
A6: 43556 | B6: 54 | C6: 66 | D6: 36 | O6: Zieldesign
A7: 43557 | B7: 38 | C7: 64 | D7: 16
A8: 43558 | B8: 97 | C8: 67 | D8: 11
A9: 43559 | B9: 40 | C9: 49 | D9: 67
A10: 43560 | B10: 2 | C10: 80 | D10: 10
A11: 43561 | B11: 16 | C11: 41 | D11: 51
A12: 43562 | B12: 88 | C12: 98 | D12: 20
A13: 43563 | B13: 15 | C13: 84 | D13: 88
A14: 43564 | B14: 13 | C14: 51 | D14: 65
A15: 43565 | B15: 38 | C15: 64 | D15: 1
A16: 43566 | B16: 52 | C16: 65 | D16: 35
A17: 43567 | B17: 29 | C17: 73 | D17: 83
A18: 43568 | B18: 59 | C18: 28 | D18: 51
... A24: 43574 | B24: 24 | C24: 65 | D24: 39
A27: Jahr | B27: Anzahl Touristen | C27: Durchschnitts-temperatur
A28: 2010 | B28: 26437 | C28: 24.436504
A29: 2011 | B29: 26536 | C29: 28.53558
A30: 2012 | B30: 32376 | C30: 34.375959
A31: 2013 | B31: 34888 | C31: 33.888223
A32: 2014 | B32: 24226 | C32: 22.225868
A33: 2015 | B33: 36575 | C33: 34.575292
A34: 2016 | B34: 26691 | C34: 27.690995
A35: 2017 | B35: 20486 | C35: 21.486271
A36: 2018 | B36: 34173 | C36: 33.173421
A37: 2019 | B37: 27905 | C37: 29.905138
A44: Wahlen der beliebtesten Getränke
A45: Mineralwasser | B45: 86.1
A46: Fruchtsaftgetränke | B46: 52.1
A47: Kaffee | B47: 47.3
A48: Cola | B48: 39.9
A49: Pils | B49: 37.8
A50: Tee | B50: 29.8
A51: Rotwein | B51: 28.5
A52: Weißwein | B52: 24.9
A53: Sekt | B53: 22.5
A54: Limonaden | B54: 21.1
...

Sheet Aufgabe6 Lösung
A1: Hier darfst du nun noch deiner "Kreativität" freien Lauf lassen. Gefordert sind verschiedene Diagrammtypen. Rechts siehst du die Mustervorlage.
A2: Die Diagramme sollten (theoretisch, du musst die jetzt nicht ausdrucken) ausgedruckt werden. Die Tabellen daneben sollen nicht gedruckt werden.
A3: Lege also bitte noch den Druckbereich fest und erstelle die Diagramme in den jeweils farbig hinterlegten Bereichen
A5: Datum | B5: Modell A | C5: Modell B | D5: Modell C
A6: 43556 | B6: 54 | C6: 66 | D6: 36
A7: 43557 | B7: 38 | C7: 64 | D7: 16
A8: 43558 | B8: 97 | C8: 67 | D8: 11
A9: 43559 | B9: 40 | C9: 49 | D9: 67
A10: 43560 | B10: 2 | C10: 80 | D10: 10
A11: 43561 | B11: 16 | C11: 41 | D11: 51
A12: 43562 | B12: 88 | C12: 98 | D12: 20
A13: 43563 | B13: 15 | C13: 84 | D13: 88
A14: 43564 | B14: 13 | C14: 51 | D14: 65
A15: 43565 | B15: 38 | C15: 64 | D15: 1
A16: 43566 | B16: 52 | C16: 65 | D16: 35
A17: 43567 | B17: 29 | C17: 73 | D17: 83
... A24: 43574 | B24: 24 | C24: 65 | D24: 39
A27: Jahr | B27: Anzahl Touristen | C27: Durchschnittstemperatur
A28: 2010 | B28: 26437 | C28: 24.436504
A29: 2011 | B29: 26536 | C29: 28.53558
A30: 2012 | B30: 32376 | C30: 34.375959
A31: 2013 | B31: 34888 | C31: 33.888223
A32: 2014 | B32: 24226 | C32: 22.225868
A33: 2015 | B33: 36575 | C33: 34.575292
A34: 2016 | B34: 26691 | C34: 27.690995
A35: 2017 | B35: 20486 | C35: 21.486271
A36: 2018 | B36: 34173 | C36: 33.173421
A37: 2019 | B37: 27905 | C37: 29.905138
A44: Wahlen der beliebtesten Getränke
A45: Mineralwasser | B45: 86.1
A46: Fruchtsaftgetränke | B46: 52.1
A47: Kaffee | B47: 47.3
A48: Cola | B48: 39.9
A49: Pils | B49: 37.8
A50: Tee | B50: 29.8
A51: Rotwein | B51: 28.5
A52: Weißwein | B52: 24.9
A53: Sekt | B53: 22.5
A54: Limonaden | B54: 21.1
A55: Joghurtgetränke | B55: 15.5
...

Sheet Auswertung
A1: Ich kann…
B2: ja | C2: nein
A3: Zellen formatieren (Schriftart, Schriftfarbe, Rahmen, Füllung etc.)
A4: Zahlenformate einstellen (Zahl, Währung, Datum etc.)
A5: Benutzerdefinierte Formate verwenden
A6: Bedingte Formatierungen erstellen
A7: Bedingte Formatierungen entfernen/ändern
A9: verschiedene Diagramme einfügen (Linie, Punkt, XY, Torte, Balken)
A10: Diagramme formatieren
A11: einen Druckbereich festlegen
A13: einfache mathematische Funktionen verwenden
A14: Logische Funktionen verwenden (WENN, UND, ODER)
A15: Autosumme verwenden (Summe, Mittelwert etc.)
A16: Autoausfüllen verwenden (automatische Reihen erzeugen)
... A32: dass Einheiten (Währungen etc) durch das Zahlenformat eingestellt werden
